<?xml version="1.0" encoding="UTF-8"?>
<testng-results skipped="0" failed="1" total="2" passed="1">
  <reporter-output>
  </reporter-output>
  <suite name="Default suite" duration-ms="24423" started-at="2020-01-02T19:23:07Z" finished-at="2020-01-02T19:23:31Z">
    <groups>
    </groups>
    <test name="Default test" duration-ms="24423" started-at="2020-01-02T19:23:07Z" finished-at="2020-01-02T19:23:31Z">
      <class name="Comments.posts.cases.Test_IT">
        <test-method status="PASS" signature="excecuteRequest()[pri:0, instance:Comments.posts.cases.Test_IT@457e2f02]" name="excecuteRequest" is-config="true" duration-ms="24395" started-at="2020-01-03T00:53:07Z" finished-at="2020-01-03T00:53:31Z">
          <reporter-output>
          </reporter-output>
        </test-method> <!-- excecuteRequest -->
        <test-method status="PASS" signature="test()[pri:0, instance:Comments.posts.cases.Test_IT@457e2f02]" name="test" duration-ms="12" started-at="2020-01-03T00:53:31Z" finished-at="2020-01-03T00:53:31Z">
          <reporter-output>
          </reporter-output>
        </test-method> <!-- test -->
        <test-method status="FAIL" signature="testOne()[pri:0, instance:Comments.posts.cases.Test_IT@457e2f02]" name="testOne" duration-ms="4" started-at="2020-01-03T00:53:31Z" finished-at="2020-01-03T00:53:31Z">
          <exception class="java.lang.AssertionError">
            <message>
              <![CDATA[The following asserts failed:
	This user doesn't exist expected [false] but found [true]]]>
            </message>
            <full-stacktrace>
              <![CDATA[java.lang.AssertionError: The following asserts failed:
	This user doesn't exist expected [false] but found [true]
	at org.testng.asserts.SoftAssert.assertAll(SoftAssert.java:43)
	at Comments.posts.cases.Test_IT.testOne(Test_IT.java:42)
	at sun.reflect.NativeMethodAccessorImpl.invoke0(Native Method)
	at sun.reflect.NativeMethodAccessorImpl.invoke(NativeMethodAccessorImpl.java:62)
	at sun.reflect.DelegatingMethodAccessorImpl.invoke(DelegatingMethodAccessorImpl.java:43)
	at java.lang.reflect.Method.invoke(Method.java:498)
	at org.testng.internal.MethodInvocationHelper.invokeMethod(MethodInvocationHelper.java:85)
	at org.testng.internal.Invoker.invokeMethod(Invoker.java:639)
	at org.testng.internal.Invoker.invokeTestMethod(Invoker.java:816)
	at org.testng.internal.Invoker.invokeTestMethods(Invoker.java:1124)
	at org.testng.internal.TestMethodWorker.invokeTestMethods(TestMethodWorker.java:125)
	at org.testng.internal.TestMethodWorker.run(TestMethodWorker.java:108)
	at org.testng.TestRunner.privateRun(TestRunner.java:774)
	at org.testng.TestRunner.run(TestRunner.java:624)
	at org.testng.SuiteRunner.runTest(SuiteRunner.java:359)
	at org.testng.SuiteRunner.runSequentially(SuiteRunner.java:354)
	at org.testng.SuiteRunner.privateRun(SuiteRunner.java:312)
	at org.testng.SuiteRunner.run(SuiteRunner.java:261)
	at org.testng.SuiteRunnerWorker.runSuite(SuiteRunnerWorker.java:52)
	at org.testng.SuiteRunnerWorker.run(SuiteRunnerWorker.java:86)
	at org.testng.TestNG.runSuitesSequentially(TestNG.java:1191)
	at org.testng.TestNG.runSuitesLocally(TestNG.java:1116)
	at org.testng.TestNG.run(TestNG.java:1024)
	at org.testng.remote.AbstractRemoteTestNG.run(AbstractRemoteTestNG.java:115)
	at org.testng.remote.RemoteTestNG.initAndRun(RemoteTestNG.java:251)
	at org.testng.remote.RemoteTestNG.main(RemoteTestNG.java:77)
]]>
            </full-stacktrace>
          </exception> <!-- java.lang.AssertionError -->
          <reporter-output>
          </reporter-output>
        </test-method> <!-- testOne -->
      </class> <!-- Comments.posts.cases.Test_IT -->
    </test> <!-- Default test -->
  </suite> <!-- Default suite -->
</testng-results>
